Workbook

Sheet Note di lettura
B2: PIANO DEI CONTI POPOLATO - Srl manifatturiera/commerciale - Esercizio 2026 - Stile Zucchetti AGO
B5: AZIENDA DI ESEMPIO
B6: Srl manifatturiera/commerciale, fatturato annuo circa 4 milioni di euro, esercizio in utile.
B7: Capitale sociale 100.000 euro, ~25 dipendenti (costo personale ~840.000), parco immobilizzato
B8: consistente (fabbricato di proprieta', macchinari, attrezzature). Indebitamento bancario di
B9: medio termine per circa 460.000 euro (mutui), oltre a finanziamento soci di 100.000 euro.
B11: STRUTTURA DEL PIANO DEI CONTI
B12: Codifica gerarchica a 3 livelli, formato MMM.CCC.SSSS:
B13: - Mastro : 3 cifre (es. 010 - Immobilizzazioni Immateriali)
B14: - Conto : 3 cifre (es. 010.005 - Costi di impianto e ampliamento)
B15: - Sottoconto: 4 cifre (es. 010.005.0001 - Costi di costituzione)
B16: Le scritture in prima nota si imputano SEMPRE ai sottoconti (foglie operative).
... B57: - 'Legenda' : abbreviazioni e principi OIC

Sheet Piano dei Conti
A1: Codice | B1: Livello | C1: Descrizione | D1: Sezione CEE | E1: Natura | F1: D/A | G1: Saldo Dare | H1: Saldo Avere | I1: Note
A2: 010 | B2: Mastro | C2: IMMOBILIZZAZIONI IMMATERIALI | D2: B.I | E2: Attivo Patrimoniale | G2: =SUMIFS($G$2:$G$455,$A$2:$A$455,"010.*",$B$2:$B$455,"Sottoconto") -> 232000 | H2: =SUMIFS($H$2:$H$455,$A$2:$A$455,"010.*",$B$2:$B$455,"Sottoconto") -> 125000
A3: 010.005 | B3: Conto | C3: Costi di impianto e di ampliamento | D3: B.I.1 | G3: =SUMIFS($G$2:$G$455,$A$2:$A$455,"010.005.*",$B$2:$B$455,"Sottoconto") -> 12000 | H3: =SUMIFS($H$2:$H$455,$A$2:$A$455,"010.005.*",$B$2:$B$455,"Sottoconto") -> 12000
A4: 010.005.0001 | B4: Sottoconto | C4: Costi di costituzione | D4: B.I.1 | E4: Attivo Patrimoniale | F4: D | G4: 8000 | H4: 0 | I4: Amm.to max 5 anni - art. 2426 c.c.
A5: 010.005.0002 | B5: Sottoconto | C5: Costi di ampliamento | D5: B.I.1 | E5: Attivo Patrimoniale | F5: D | G5: 4000 | H5: 0
A6: 010.005.9001 | B6: Sottoconto | C6: F.do amm.to costi di impianto e amplto | D6: B.I.1 | E6: Rettifica (fondo) | F6: A | G6: 0 | H6: 12000 | I6: Fondo rettificativo
A7: 010.010 | B7: Conto | C7: Costi di sviluppo | D7: B.I.2 | G7: =SUMIFS($G$2:$G$455,$A$2:$A$455,"010.010.*",$B$2:$B$455,"Sottoconto") -> 0 | H7: =SUMIFS($H$2:$H$455,$A$2:$A$455,"010.010.*",$B$2:$B$455,"Sottoconto") -> 0
A8: 010.010.0001 | B8: Sottoconto | C8: Costi di sviluppo capitalizzati | D8: B.I.2 | E8: Attivo Patrimoniale | F8: D | G8: 0 | H8: 0 | I8: Solo se ricorrono condizioni OIC 24
A9: 010.010.9001 | B9: Sottoconto | C9: F.do amm.to costi di sviluppo | D9: B.I.2 | E9: Rettifica (fondo) | F9: A | G9: 0 | H9: 0
A10: 010.015 | B10: Conto | C10: Diritti di brevetto industriale | D10: B.I.3 | G10: =SUMIFS($G$2:$G$455,$A$2:$A$455,"010.015.*",$B$2:$B$455,"Sottoconto") -> 30000 | H10: =SUMIFS($H$2:$H$455,$A$2:$A$455,"010.015.*",$B$2:$B$455,"Sottoconto") -> 12000
A11: 010.015.0001 | B11: Sottoconto | C11: Brevetti industriali | D11: B.I.3 | E11: Attivo Patrimoniale | F11: D | G11: 0 | H11: 0
A12: 010.015.0002 | B12: Sottoconto | C12: Software applicativo di proprieta' | D12: B.I.3 | E12: Attivo Patrimoniale | F12: D | G12: 30000 | H12: 0
A13: 010.015.0003 | B13: Sottoconto | C13: Diritti d'autore | D13: B.I.3 | E13: Attivo Patrimoniale | F13: D | G13: 0 | H13: 0
A14: 010.015.9001 | B14: Sottoconto | C14: F.do amm.to brevetti | D14: B.I.3 | E14: Rettifica (fondo) | F14: A | G14: 0 | H14: 0
A15: 010.015.9002 | B15: Sottoconto | C15: F.do amm.to software | D15: B.I.3 | E15: Rettifica (fondo) | F15: A | G15: 0 | H15: 12000
A16: 010.020 | B16: Conto | C16: Concessioni, licenze, marchi e simili | D16: B.I.4 | G16: =SUMIFS($G$2:$G$455,$A$2:$A$455,"010.020.*",$B$2:$B$455,"Sottoconto") -> 50000 | H16: =SUMIFS($H$2:$H$455,$A$2:$A$455,"010.020.*",$B$2:$B$455,"Sottoconto") -> 25000
A17: 010.020.0001 | B17: Sottoconto | C17: Marchi | D17: B.I.4 | E17: Attivo Patrimoniale | F17: D | G17: 50000 | H17: 0
A18: 010.020.0002 | B18: Sottoconto | C18: Licenze d'uso software (capitalizzate) | D18: B.I.4 | E18: Attivo Patrimoniale | F18: D | G18: 0 | H18: 0
A19: 010.020.0003 | B19: Sottoconto | C19: Concessioni | D19: B.I.4 | E19: Attivo Patrimoniale | F19: D | G19: 0 | H19: 0
A20: 010.020.9001 | B20: Sottoconto | C20: F.do amm.to marchi | D20: B.I.4 | E20: Rettifica (fondo) | F20: A | G20: 0 | H20: 25000
A21: 010.020.9002 | B21: Sottoconto | C21: F.do amm.to licenze software | D21: B.I.4 | E21: Rettifica (fondo) | F21: A | G21: 0 | H21: 0
A22: 010.020.9003 | B22: Sottoconto | C22: F.do amm.to concessioni | D22: B.I.4 | E22: Rettifica (fondo) | F22: A | G22: 0 | H22: 0
A23: 010.025 | B23: Conto | C23: Avviamento | D23: B.I.5 | G23: =SUMIFS($G$2:$G$455,$A$2:$A$455,"010.025.*",$B$2:$B$455,"Sottoconto") -> 100000 | H23: =SUMIFS($H$2:$H$455,$A$2:$A$455,"010.025.*",$B$2:$B$455,"Sottoconto") -> 60000
A24: 010.025.0001 | B24: Sottoconto | C24: Avviamento | D24: B.I.5 | E24: Attivo Patrimoniale | F24: D | G24: 100000 | H24: 0 | I24: Solo se acquisito a titolo oneroso
A25: 010.025.9001 | B25: Sottoconto | C25: F.do amm.to avviamento | D25: B.I.5 | E25: Rettifica (fondo) | F25: A | G25: 0 | H25: 60000 | I25: Vita utile, max 10 anni in via residuale
A26: 010.030 | B26: Conto | C26: Immob. immateriali in corso e acconti | D26: B.I.6 | G26: =SUMIFS($G$2:$G$455,$A$2:$A$455,"010.030.*",$B$2:$B$455,"Sottoconto") -> 0 | H26: =SUMIFS($H$2:$H$455,$A$2:$A$455,"010.030.*",$B$2:$B$455,"Sottoconto") -> 0
A27: 010.030.0001 | B27: Sottoconto | C27: Immobilizzazioni immateriali in corso | D27: B.I.6 | E27: Attivo Patrimoniale | F27: D | G27: 0 | H27: 0
A28: 010.030.0002 | B28: Sottoconto | C28: Acconti su immob. immateriali | D28: B.I.6 | E28: Attivo Patrimoniale | F28: D | G28: 0 | H28: 0
A29: 010.035 | B29: Conto | C29: Altre immobilizzazioni immateriali | D29: B.I.7 | G29: =SUMIFS($G$2:$G$455,$A$2:$A$455,"010.035.*",$B$2:$B$455,"Sottoconto") -> 40000 | H29: =SUMIFS($H$2:$H$455,$A$2:$A$455,"010.035.*",$B$2:$B$455,"Sottoconto") -> 16000
A30: 010.035.0001 | B30: Sottoconto | C30: Migliorie su beni di terzi | D30: B.I.7 | E30: Attivo Patrimoniale | F30: D | G30: 40000 | H30: 0 | I30: Lavori su immobile in locazione
A31: 010.035.0002 | B31: Sottoconto | C31: Spese pluriennali diverse | D31: B.I.7 | E31: Attivo Patrimoniale | F31: D | G31: 0 | H31: 0
A32: 010.035.9001 | B32: Sottoconto | C32: F.do amm.to migliorie su beni di terzi | D32: B.I.7 | E32: Rettifica (fondo) | F32: A | G32: 0 | H32: 16000
A33: 010.035.9002 | B33: Sottoconto | C33: F.do amm.to altre immob. immateriali | D33: B.I.7 | E33: Rettifica (fondo) | F33: A | G33: 0 | H33: 0
A34: 020 | B34: Mastro | C34: IMMOBILIZZAZIONI MATERIALI | D34: B.II | E34: Attivo Patrimoniale | G34: =SUMIFS($G$2:$G$455,$A$2:$A$455,"020.*",$B$2:$B$455,"Sottoconto") -> 1825000 | H34: =SUMIFS($H$2:$H$455,$A$2:$A$455,"020.*",$B$2:$B$455,"Sottoconto") -> 736500
A35: 020.005 | B35: Conto | C35: Terreni e fabbricati | D35: B.II.1 | G35: =SUMIFS($G$2:$G$455,$A$2:$A$455,"020.005.*",$B$2:$B$455,"Sottoconto") -> 800000 | H35: =SUMIFS($H$2:$H$455,$A$2:$A$455,"020.005.*",$B$2:$B$455,"Sottoconto") -> 240000
A36: 020.005.0001 | B36: Sottoconto | C36: Terreni | D36: B.II.1 | E36: Attivo Patrimoniale | F36: D | G36: 200000 | H36: 0 | I36: Non ammortizzabili - OIC 16
A37: 020.005.0002 | B37: Sottoconto | C37: Fabbricati industriali | D37: B.II.1 | E37: Attivo Patrimoniale | F37: D | G37: 600000 | H37: 0
A38: 020.005.0003 | B38: Sottoconto | C38: Fabbricati civili strumentali | D38: B.II.1 | E38: Attivo Patrimoniale | F38: D | G38: 0 | H38: 0
A39: 020.005.0004 | B39: Sottoconto | C39: Costruzioni leggere | D39: B.II.1 | E39: Attivo Patrimoniale | F39: D | G39: 0 | H39: 0
A40: 020.005.9002 | B40: Sottoconto | C40: F.do amm.to fabbricati industriali | D40: B.II.1 | E40: Rettifica (fondo) | F40: A | G40: 0 | H40: 240000
...

Sheet Bilancio Verifica
A1: BILANCIO DI VERIFICA AL 31/12/2026 - Sintesi per Mastro
A2: Mastro | B2: Descrizione | C2: Saldo Dare | D2: Saldo Avere | E2: Saldo Netto
A3: 010 | B3: IMMOBILIZZAZIONI IMMATERIALI | C3: ='Piano dei Conti'!G2 -> 232000 | D3: ='Piano dei Conti'!H2 -> 125000 | E3: =C3-D3 -> 107000
A4: 020 | B4: IMMOBILIZZAZIONI MATERIALI | C4: ='Piano dei Conti'!G34 -> 1825000 | D4: ='Piano dei Conti'!H34 -> 736500 | E4: =C4-D4 -> 1088500
A5: 030 | B5: IMMOBILIZZAZIONI FINANZIARIE | C5: ='Piano dei Conti'!G78 -> 25000 | D5: ='Piano dei Conti'!H78 -> 0 | E5: =C5-D5 -> 25000
A6: 040 | B6: RIMANENZE | C6: ='Piano dei Conti'!G95 -> 390000 | D6: ='Piano dei Conti'!H95 -> 0 | E6: =C6-D6 -> 390000
A7: 050 | B7: CREDITI DELL'ATTIVO CIRCOLANTE | C7: ='Piano dei Conti'!G110 -> 1157000 | D7: ='Piano dei Conti'!H110 -> 60000 | E7: =C7-D7 -> 1097000
A8: 060 | B8: ATTIVITA' FINANZIARIE NON IMMOBILIZZATE | C8: ='Piano dei Conti'!G146 -> 0 | D8: ='Piano dei Conti'!H146 -> 0 | E8: =C8-D8 -> 0
A9: 070 | B9: DISPONIBILITA' LIQUIDE | C9: ='Piano dei Conti'!G158 -> 132300 | D9: ='Piano dei Conti'!H158 -> 0 | E9: =C9-D9 -> 132300
A10: 080 | B10: RATEI E RISCONTI ATTIVI | C10: ='Piano dei Conti'!G171 -> 8000 | D10: ='Piano dei Conti'!H171 -> 0 | E10: =C10-D10 -> 8000
A11: 100 | B11: PATRIMONIO NETTO | C11: ='Piano dei Conti'!G177 -> 0 | D11: ='Piano dei Conti'!H177 -> 499300 | E11: =C11-D11 -> -499300
A12: 110 | B12: FONDI PER RISCHI E ONERI | C12: ='Piano dei Conti'!G204 -> 0 | D12: ='Piano dei Conti'!H204 -> 45000 | E12: =C12-D12 -> -45000
A13: 120 | B13: TRATTAMENTO DI FINE RAPPORTO | C13: ='Piano dei Conti'!G217 -> 0 | D13: ='Piano dei Conti'!H217 -> 145000 | E13: =C13-D13 -> -145000
A14: 130 | B14: DEBITI | C14: ='Piano dei Conti'!G220 -> 0 | D14: ='Piano dei Conti'!H220 -> 1761800 | E14: =C14-D14 -> -1761800
A15: 180 | B15: RATEI E RISCONTI PASSIVI | C15: ='Piano dei Conti'!G280 -> 0 | D15: ='Piano dei Conti'!H280 -> 8000 | E15: =C15-D15 -> -8000
A16: 300 | B16: VALORE DELLA PRODUZIONE | C16: ='Piano dei Conti'!G286 -> 25000 | D16: ='Piano dei Conti'!H286 -> 4053000 | E16: =C16-D16 -> -4028000
A17: 200 | B17: COSTI DELLA PRODUZIONE | C17: ='Piano dei Conti'!G314 -> 3462100 | D17: ='Piano dei Conti'!H314 -> 40000 | E17: =C17-D17 -> 3422100
A18: 400 | B18: PROVENTI E ONERI FINANZIARI | C18: ='Piano dei Conti'!G410 -> 0 | D18: ='Piano dei Conti'!H410 -> 5800 | E18: =C18-D18 -> -5800
A19: 410 | B19: INTERESSI E ALTRI ONERI FINANZIARI | C19: ='Piano dei Conti'!G424 -> 56000 | D19: ='Piano dei Conti'!H424 -> 0 | E19: =C19-D19 -> 56000
A20: 420 | B20: RETTIFICHE DI VALORE ATTIVITA' E PASS. FIN. | C20: ='Piano dei Conti'!G434 -> 0 | D20: ='Piano dei Conti'!H434 -> 0 | E20: =C20-D20 -> 0
A21: 480 | B21: IMPOSTE SUL REDDITO DELL'ESERCIZIO | C21: ='Piano dei Conti'!G445 -> 170500 | D21: ='Piano dei Conti'!H445 -> 3500 | E21: =C21-D21 -> 167000
A22: 500 | B22: RISULTATO DELL'ESERCIZIO | C22: ='Piano dei Conti'!G453 -> 0 | D22: ='Piano dei Conti'!H453 -> 0 | E22: =C22-D22 -> 0
B23: TOTALE BILANCIO DI VERIFICA | C23: =SUM(C3:C22) -> 7482900 | D23: =SUM(D3:D22) -> 7482900 | E23: =C23-D23 -> 0
B24: QUADRATURA | C24: =C23-D23 -> 0 | D24: =IF(ROUND(C23-D23,2)=0,"QUADRATO","SBILANCIO") -> QUADRATO

Sheet SP CEE Valorizzato
A1: STATO PATRIMONIALE CIVILISTICO (artt. 2424 c.c.) - VALORIZZATO al 31/12/2026
A3: ATTIVO
A4: A) CREDITI VERSO SOCI PER VERSAMENTI ANCORA DOVUTI | B4: 0
A5: B) IMMOBILIZZAZIONI
A6: I. Immobilizzazioni immateriali | B6: =SUMIFS('Piano dei Conti'!G2:G455,'Piano dei Conti'!A2:A455,"010.*",'Piano dei Conti'!B2:B455,"Sottoconto")-SUMIFS('Piano dei Conti'!H2:H455,'Piano dei Conti'!A2:A455,"010.*",'Piano dei Conti'!B2:B455,"Sottoconto") -> 107000
A7: 1) Costi di impianto e di ampliamento | B7: =SUMIFS('Piano dei Conti'!G2:G455,'Piano dei Conti'!A2:A455,"010.005.*",'Piano dei Conti'!B2:B455,"Sottoconto")-SUMIFS('Piano dei Conti'!H2:H455,'Piano dei Conti'!A2:A455,"010.005.*",'Piano dei Conti'!B2:B455,"Sottoconto") -> 0
A8: 3) Diritti brev. ind., utilizzo opere ingegno | B8: =SUMIFS('Piano dei Conti'!G2:G455,'Piano dei Conti'!A2:A455,"010.015.*",'Piano dei Conti'!B2:B455,"Sottoconto")-SUMIFS('Piano dei Conti'!H2:H455,'Piano dei Conti'!A2:A455,"010.015.*",'Piano dei Conti'!B2:B455,"Sottoconto") -> 18000
A9: 4) Concessioni, licenze, marchi e simili | B9: =SUMIFS('Piano dei Conti'!G2:G455,'Piano dei Conti'!A2:A455,"010.020.*",'Piano dei Conti'!B2:B455,"Sottoconto")-SUMIFS('Piano dei Conti'!H2:H455,'Piano dei Conti'!A2:A455,"010.020.*",'Piano dei Conti'!B2:B455,"Sottoconto") -> 25000
A10: 5) Avviamento | B10: =SUMIFS('Piano dei Conti'!G2:G455,'Piano dei Conti'!A2:A455,"010.025.*",'Piano dei Conti'!B2:B455,"Sottoconto")-SUMIFS('Piano dei Conti'!H2:H455,'Piano dei Conti'!A2:A455,"010.025.*",'Piano dei Conti'!B2:B455,"Sottoconto") -> 40000
A11: 7) Altre immobilizzazioni immateriali | B11: =SUMIFS('Piano dei Conti'!G2:G455,'Piano dei Conti'!A2:A455,"010.035.*",'Piano dei Conti'!B2:B455,"Sottoconto")-SUMIFS('Piano dei Conti'!H2:H455,'Piano dei Conti'!A2:A455,"010.035.*",'Piano dei Conti'!B2:B455,"Sottoconto") -> 24000
A12: II. Immobilizzazioni materiali | B12: =SUMIFS('Piano dei Conti'!G2:G455,'Piano dei Conti'!A2:A455,"020.*",'Piano dei Conti'!B2:B455,"Sottoconto")-SUMIFS('Piano dei Conti'!H2:H455,'Piano dei Conti'!A2:A455,"020.*",'Piano dei Conti'!B2:B455,"Sottoconto") -> 1088500
A13: 1) Terreni e fabbricati | B13: =SUMIFS('Piano dei Conti'!G2:G455,'Piano dei Conti'!A2:A455,"020.005.*",'Piano dei Conti'!B2:B455,"Sottoconto")-SUMIFS('Piano dei Conti'!H2:H455,'Piano dei Conti'!A2:A455,"020.005.*",'Piano dei Conti'!B2:B455,"Sottoconto") -> 560000
A14: 2) Impianti e macchinario | B14: =SUMIFS('Piano dei Conti'!G2:G455,'Piano dei Conti'!A2:A455,"020.010.*",'Piano dei Conti'!B2:B455,"Sottoconto")-SUMIFS('Piano dei Conti'!H2:H455,'Piano dei Conti'!A2:A455,"020.010.*",'Piano dei Conti'!B2:B455,"Sottoconto") -> 415000
A15: 3) Attrezzature industriali e commerciali | B15: =SUMIFS('Piano dei Conti'!G2:G455,'Piano dei Conti'!A2:A455,"020.015.*",'Piano dei Conti'!B2:B455,"Sottoconto")-SUMIFS('Piano dei Conti'!H2:H455,'Piano dei Conti'!A2:A455,"020.015.*",'Piano dei Conti'!B2:B455,"Sottoconto") -> 24000
A16: 4) Altri beni | B16: =SUMIFS('Piano dei Conti'!G2:G455,'Piano dei Conti'!A2:A455,"020.020.*",'Piano dei Conti'!B2:B455,"Sottoconto")-SUMIFS('Piano dei Conti'!H2:H455,'Piano dei Conti'!A2:A455,"020.020.*",'Piano dei Conti'!B2:B455,"Sottoconto") -> 89500
A17: III. Immobilizzazioni finanziarie | B17: =SUMIFS('Piano dei Conti'!G2:G455,'Piano dei Conti'!A2:A455,"030.*",'Piano dei Conti'!B2:B455,"Sottoconto")-SUMIFS('Piano dei Conti'!H2:H455,'Piano dei Conti'!A2:A455,"030.*",'Piano dei Conti'!B2:B455,"Sottoconto") -> 25000
A18: 1.d) Partecipazioni in altre imprese | B18: =SUMIFS('Piano dei Conti'!G2:G455,'Piano dei Conti'!A2:A455,"030.005.0005",'Piano dei Conti'!B2:B455,"Sottoconto")-SUMIFS('Piano dei Conti'!H2:H455,'Piano dei Conti'!A2:A455,"030.005.0005",'Piano dei Conti'!B2:B455,"Sottoconto") -> 25000
A19: Totale Immobilizzazioni (B) | B19: =B6+B12+B17 -> 1220500
A20: C) ATTIVO CIRCOLANTE
A21: I. Rimanenze | B21: =SUMIFS('Piano dei Conti'!G2:G455,'Piano dei Conti'!A2:A455,"040.*",'Piano dei Conti'!B2:B455,"Sottoconto")-SUMIFS('Piano dei Conti'!H2:H455,'Piano dei Conti'!A2:A455,"040.*",'Piano dei Conti'!B2:B455,"Sottoconto") -> 390000
A22: 1) Materie prime, sussidiarie, di consumo | B22: =SUMIFS('Piano dei Conti'!G2:G455,'Piano dei Conti'!A2:A455,"040.005.*",'Piano dei Conti'!B2:B455,"Sottoconto")-SUMIFS('Piano dei Conti'!H2:H455,'Piano dei Conti'!A2:A455,"040.005.*",'Piano dei Conti'!B2:B455,"Sottoconto") -> 180000
A23: 2) Prodotti in corso di lavorazione e semilavorati | B23: =SUMIFS('Piano dei Conti'!G2:G455,'Piano dei Conti'!A2:A455,"040.010.*",'Piano dei Conti'!B2:B455,"Sottoconto")-SUMIFS('Piano dei Conti'!H2:H455,'Piano dei Conti'!A2:A455,"040.010.*",'Piano dei Conti'!B2:B455,"Sottoconto") -> 50000
A24: 4) Prodotti finiti e merci | B24: =SUMIFS('Piano dei Conti'!G2:G455,'Piano dei Conti'!A2:A455,"040.020.*",'Piano dei Conti'!B2:B455,"Sottoconto")-SUMIFS('Piano dei Conti'!H2:H455,'Piano dei Conti'!A2:A455,"040.020.*",'Piano dei Conti'!B2:B455,"Sottoconto") -> 160000
A25: II. Crediti | B25: =SUMIFS('Piano dei Conti'!G2:G455,'Piano dei Conti'!A2:A455,"050.*",'Piano dei Conti'!B2:B455,"Sottoconto")-SUMIFS('Piano dei Conti'!H2:H455,'Piano dei Conti'!A2:A455,"050.*",'Piano dei Conti'!B2:B455,"Sottoconto") -> 1097000
A26: 1) Verso clienti (al netto fondo svalutazione) | B26: =SUMIFS('Piano dei Conti'!G2:G455,'Piano dei Conti'!A2:A455,"050.005.*",'Piano dei Conti'!B2:B455,"Sottoconto")-SUMIFS('Piano dei Conti'!H2:H455,'Piano dei Conti'!A2:A455,"050.005.*",'Piano dei Conti'!B2:B455,"Sottoconto") -> 1045000
A27: 5-bis) Crediti tributari | B27: =SUMIFS('Piano dei Conti'!G2:G455,'Piano dei Conti'!A2:A455,"050.030.*",'Piano dei Conti'!B2:B455,"Sottoconto")-SUMIFS('Piano dei Conti'!H2:H455,'Piano dei Conti'!A2:A455,"050.030.*",'Piano dei Conti'!B2:B455,"Sottoconto") -> 23500
A28: 5-ter) Imposte anticipate | B28: =SUMIFS('Piano dei Conti'!G2:G455,'Piano dei Conti'!A2:A455,"050.035.*",'Piano dei Conti'!B2:B455,"Sottoconto")-SUMIFS('Piano dei Conti'!H2:H455,'Piano dei Conti'!A2:A455,"050.035.*",'Piano dei Conti'!B2:B455,"Sottoconto") -> 18000
A29: 5-quater) Verso altri | B29: =SUMIFS('Piano dei Conti'!G2:G455,'Piano dei Conti'!A2:A455,"050.040.*",'Piano dei Conti'!B2:B455,"Sottoconto")-SUMIFS('Piano dei Conti'!H2:H455,'Piano dei Conti'!A2:A455,"050.040.*",'Piano dei Conti'!B2:B455,"Sottoconto") -> 10500
A30: IV. Disponibilita' liquide | B30: =SUMIFS('Piano dei Conti'!G2:G455,'Piano dei Conti'!A2:A455,"070.*",'Piano dei Conti'!B2:B455,"Sottoconto")-SUMIFS('Piano dei Conti'!H2:H455,'Piano dei Conti'!A2:A455,"070.*",'Piano dei Conti'!B2:B455,"Sottoconto") -> 132300
A31: 1) Depositi bancari e postali | B31: =SUMIFS('Piano dei Conti'!G2:G455,'Piano dei Conti'!A2:A455,"070.005.*",'Piano dei Conti'!B2:B455,"Sottoconto")-SUMIFS('Piano dei Conti'!H2:H455,'Piano dei Conti'!A2:A455,"070.005.*",'Piano dei Conti'!B2:B455,"Sottoconto") -> 130000
A32: 3) Denaro e valori in cassa | B32: =SUMIFS('Piano dei Conti'!G2:G455,'Piano dei Conti'!A2:A455,"070.015.*",'Piano dei Conti'!B2:B455,"Sottoconto")-SUMIFS('Piano dei Conti'!H2:H455,'Piano dei Conti'!A2:A455,"070.015.*",'Piano dei Conti'!B2:B455,"Sottoconto") -> 2300
A33: Totale Attivo Circolante (C) | B33: =B21+B25+B30 -> 1619300
A34: D) RATEI E RISCONTI ATTIVI | B34: =SUMIFS('Piano dei Conti'!G2:G455,'Piano dei Conti'!A2:A455,"080.*",'Piano dei Conti'!B2:B455,"Sottoconto")-SUMIFS('Piano dei Conti'!H2:H455,'Piano dei Conti'!A2:A455,"080.*",'Piano dei Conti'!B2:B455,"Sottoconto") -> 8000
A36: TOTALE ATTIVO | B36: =B19+B33+B34 -> 2847800
A38: PASSIVO E PATRIMONIO NETTO
A39: A) PATRIMONIO NETTO
A40: I. Capitale | B40: =SUMIFS('Piano dei Conti'!H2:H455,'Piano dei Conti'!A2:A455,"100.005.*",'Piano dei Conti'!B2:B455,"Sottoconto")-SUMIFS('Piano dei Conti'!G2:G455,'Piano dei Conti'!A2:A455,"100.005.*",'Piano dei Conti'!B2:B455,"Sottoconto") -> 100000
A41: IV. Riserva legale | B41: =SUMIFS('Piano dei Conti'!H2:H455,'Piano dei Conti'!A2:A455,"100.020.*",'Piano dei Conti'!B2:B455,"Sottoconto")-SUMIFS('Piano dei Conti'!G2:G455,'Piano dei Conti'!A2:A455,"100.020.*",'Piano dei Conti'!B2:B455,"Sottoconto") -> 20000
A42: VI. Altre riserve (straord. + vers. soci c/cap) | B42: =SUMIFS('Piano dei Conti'!H2:H455,'Piano dei Conti'!A2:A455,"100.030.*",'Piano dei Conti'!B2:B455,"Sottoconto")-SUMIFS('Piano dei Conti'!G2:G455,'Piano dei Conti'!A2:A455,"100.030.*",'Piano dei Conti'!B2:B455,"Sottoconto") -> 234000
A43: VIII. Utili (perdite) portati a nuovo | B43: =SUMIFS('Piano dei Conti'!H2:H455,'Piano dei Conti'!A2:A455,"100.040.*",'Piano dei Conti'!B2:B455,"Sottoconto")-SUMIFS('Piano dei Conti'!G2:G455,'Piano dei Conti'!A2:A455,"100.040.*",'Piano dei Conti'!B2:B455,"Sottoconto") -> 145300
...

Sheet CE CEE Valorizzato
A1: CONTO ECONOMICO CIVILISTICO (art. 2425 c.c.) - VALORIZZATO esercizio 2026
A3: A) VALORE DELLA PRODUZIONE
A4: 1) Ricavi delle vendite e delle prestazioni | B4: =-1*(SUMIFS('Piano dei Conti'!G2:G455,'Piano dei Conti'!A2:A455,"300.005.*",'Piano dei Conti'!B2:B455,"Sottoconto")-SUMIFS('Piano dei Conti'!H2:H455,'Piano dei Conti'!A2:A455,"300.005.*",'Piano dei Conti'!B2:B455,"Sottoconto")) -> 3925000
A5: 2) Variazioni rim. prodotti in corso, semilav., finiti | B5: =-1*(SUMIFS('Piano dei Conti'!G2:G455,'Piano dei Conti'!A2:A455,"300.010.*",'Piano dei Conti'!B2:B455,"Sottoconto")-SUMIFS('Piano dei Conti'!H2:H455,'Piano dei Conti'!A2:A455,"300.010.*",'Piano dei Conti'!B2:B455,"Sottoconto")) -> 45000
A6: 5) Altri ricavi e proventi | B6: =-1*(SUMIFS('Piano dei Conti'!G2:G455,'Piano dei Conti'!A2:A455,"300.025.*",'Piano dei Conti'!B2:B455,"Sottoconto")-SUMIFS('Piano dei Conti'!H2:H455,'Piano dei Conti'!A2:A455,"300.025.*",'Piano dei Conti'!B2:B455,"Sottoconto")) -> 58000
A7: di cui contributi in c/esercizio | B7: =-1*(SUMIFS('Piano dei Conti'!G2:G455,'Piano dei Conti'!A2:A455,"300.025.0003",'Piano dei Conti'!B2:B455,"Sottoconto")-SUMIFS('Piano dei Conti'!H2:H455,'Piano dei Conti'!A2:A455,"300.025.0003",'Piano dei Conti'!B2:B455,"Sottoconto")) -> 8000
A8: Totale A) | B8: =B4+B5+B6 -> 4028000
A10: B) COSTI DELLA PRODUZIONE
A11: 6) Costi materie prime, sussidiarie, consumo, merci | B11: =SUMIFS('Piano dei Conti'!G2:G455,'Piano dei Conti'!A2:A455,"200.005.*",'Piano dei Conti'!B2:B455,"Sottoconto")-SUMIFS('Piano dei Conti'!H2:H455,'Piano dei Conti'!A2:A455,"200.005.*",'Piano dei Conti'!B2:B455,"Sottoconto") -> 1453000
A12: 7) Costi per servizi | B12: =SUMIFS('Piano dei Conti'!G2:G455,'Piano dei Conti'!A2:A455,"200.010.*",'Piano dei Conti'!B2:B455,"Sottoconto")-SUMIFS('Piano dei Conti'!H2:H455,'Piano dei Conti'!A2:A455,"200.010.*",'Piano dei Conti'!B2:B455,"Sottoconto") -> 758000
A13: 8) Costi per godimento beni di terzi | B13: =SUMIFS('Piano dei Conti'!G2:G455,'Piano dei Conti'!A2:A455,"200.015.*",'Piano dei Conti'!B2:B455,"Sottoconto")-SUMIFS('Piano dei Conti'!H2:H455,'Piano dei Conti'!A2:A455,"200.015.*",'Piano dei Conti'!B2:B455,"Sottoconto") -> 165000
A14: 9) Costi per il personale | B14: =SUMIFS('Piano dei Conti'!G2:G455,'Piano dei Conti'!A2:A455,"200.020.*",'Piano dei Conti'!B2:B455,"Sottoconto")-SUMIFS('Piano dei Conti'!H2:H455,'Piano dei Conti'!A2:A455,"200.020.*",'Piano dei Conti'!B2:B455,"Sottoconto") -> 837000
A15: a) salari e stipendi | B15: =SUMIFS('Piano dei Conti'!G2:G455,'Piano dei Conti'!A2:A455,"200.020.0001",'Piano dei Conti'!B2:B455,"Sottoconto")-SUMIFS('Piano dei Conti'!H2:H455,'Piano dei Conti'!A2:A455,"200.020.0001",'Piano dei Conti'!B2:B455,"Sottoconto") -> 580000
A16: b) oneri sociali | B16: =SUMIFS('Piano dei Conti'!G2:G455,'Piano dei Conti'!A2:A455,"200.020.0002",'Piano dei Conti'!B2:B455,"Sottoconto")-SUMIFS('Piano dei Conti'!H2:H455,'Piano dei Conti'!A2:A455,"200.020.0002",'Piano dei Conti'!B2:B455,"Sottoconto")+SUMIFS('Piano dei Conti'!G2:G455,'Piano dei Conti'!A2:A455,"200.020.0003",'Piano dei Conti'!B2:B455,"Sottoconto")-SUMIFS('Piano dei Conti'!H2:H455,'Piano dei Conti'!A2:A455,"200.020.0003",'Piano dei Conti'!B2:B455,"Sottoconto") -> 187000
A17: c) trattamento di fine rapporto | B17: =SUMIFS('Piano dei Conti'!G2:G455,'Piano dei Conti'!A2:A455,"200.020.0004",'Piano dei Conti'!B2:B455,"Sottoconto")-SUMIFS('Piano dei Conti'!H2:H455,'Piano dei Conti'!A2:A455,"200.020.0004",'Piano dei Conti'!B2:B455,"Sottoconto") -> 42000
A18: e) altri costi | B18: =SUMIFS('Piano dei Conti'!G2:G455,'Piano dei Conti'!A2:A455,"200.020.0006",'Piano dei Conti'!B2:B455,"Sottoconto")-SUMIFS('Piano dei Conti'!H2:H455,'Piano dei Conti'!A2:A455,"200.020.0006",'Piano dei Conti'!B2:B455,"Sottoconto")+SUMIFS('Piano dei Conti'!G2:G455,'Piano dei Conti'!A2:A455,"200.020.0007",'Piano dei Conti'!B2:B455,"Sottoconto")-SUMIFS('Piano dei Conti'!H2:H455,'Piano dei Conti'!A2:A455,"200.020.0007",'Piano dei Conti'!B2:B455,"Sottoconto")+SUMIFS('Piano dei Conti'!G2:G455,'Piano dei Conti'!A2:A455,"200.020.0008",'Piano dei Conti'!B2:B455,"Sottoconto")-SUMIFS('Piano dei Conti'!H2:H455,'Piano dei Conti'!A2:A455,"200.020.0008",'Piano dei Conti'!B2:B455,"Sottoconto") -> 28000
A19: 10) Ammortamenti e svalutazioni | B19: =SUMIFS('Piano dei Conti'!G2:G455,'Piano dei Conti'!A2:A455,"200.025.*",'Piano dei Conti'!B2:B455,"Sottoconto")-SUMIFS('Piano dei Conti'!H2:H455,'Piano dei Conti'!A2:A455,"200.025.*",'Piano dei Conti'!B2:B455,"Sottoconto") -> 185000
A20: a) amm.to immob. immateriali | B20: =SUMIFS('Piano dei Conti'!G2:G455,'Piano dei Conti'!A2:A455,"200.025.0001",'Piano dei Conti'!B2:B455,"Sottoconto")-SUMIFS('Piano dei Conti'!H2:H455,'Piano dei Conti'!A2:A455,"200.025.0001",'Piano dei Conti'!B2:B455,"Sottoconto") -> 28000
A21: b) amm.to immob. materiali | B21: =SUMIFS('Piano dei Conti'!G2:G455,'Piano dei Conti'!A2:A455,"200.025.0002",'Piano dei Conti'!B2:B455,"Sottoconto")-SUMIFS('Piano dei Conti'!H2:H455,'Piano dei Conti'!A2:A455,"200.025.0002",'Piano dei Conti'!B2:B455,"Sottoconto") -> 145000
A22: d) svalutazione crediti attivo circolante | B22: =SUMIFS('Piano dei Conti'!G2:G455,'Piano dei Conti'!A2:A455,"200.025.0004",'Piano dei Conti'!B2:B455,"Sottoconto")-SUMIFS('Piano dei Conti'!H2:H455,'Piano dei Conti'!A2:A455,"200.025.0004",'Piano dei Conti'!B2:B455,"Sottoconto") -> 12000
A23: 11) Variazione rim. materie prime, sussidiarie, consumo, merci | B23: =SUMIFS('Piano dei Conti'!G2:G455,'Piano dei Conti'!A2:A455,"200.030.*",'Piano dei Conti'!B2:B455,"Sottoconto")-SUMIFS('Piano dei Conti'!H2:H455,'Piano dei Conti'!A2:A455,"200.030.*",'Piano dei Conti'!B2:B455,"Sottoconto") -> -20000
A24: 12) Accantonamenti per rischi | B24: =SUMIFS('Piano dei Conti'!G2:G455,'Piano dei Conti'!A2:A455,"200.035.*",'Piano dei Conti'!B2:B455,"Sottoconto")-SUMIFS('Piano dei Conti'!H2:H455,'Piano dei Conti'!A2:A455,"200.035.*",'Piano dei Conti'!B2:B455,"Sottoconto") -> 8000
A25: 14) Oneri diversi di gestione | B25: =SUMIFS('Piano dei Conti'!G2:G455,'Piano dei Conti'!A2:A455,"200.045.*",'Piano dei Conti'!B2:B455,"Sottoconto")-SUMIFS('Piano dei Conti'!H2:H455,'Piano dei Conti'!A2:A455,"200.045.*",'Piano dei Conti'!B2:B455,"Sottoconto") -> 36100
A26: Totale B) | B26: =B11+B12+B13+B14+B19+B23+B24+B25 -> 3422100
A28: DIFFERENZA TRA VALORE E COSTI DELLA PRODUZIONE (A-B) | B28: =B8-B26 -> 605900
A30: C) PROVENTI E ONERI FINANZIARI
A31: 16) Altri proventi finanziari | B31: =-1*(SUMIFS('Piano dei Conti'!G2:G455,'Piano dei Conti'!A2:A455,"400.010.*",'Piano dei Conti'!B2:B455,"Sottoconto")-SUMIFS('Piano dei Conti'!H2:H455,'Piano dei Conti'!A2:A455,"400.010.*",'Piano dei Conti'!B2:B455,"Sottoconto")) -> 5800
A32: 17) Interessi e altri oneri finanziari | B32: =SUMIFS('Piano dei Conti'!G2:G455,'Piano dei Conti'!A2:A455,"410.005.*",'Piano dei Conti'!B2:B455,"Sottoconto")-SUMIFS('Piano dei Conti'!H2:H455,'Piano dei Conti'!A2:A455,"410.005.*",'Piano dei Conti'!B2:B455,"Sottoconto") -> 56000
A33: Totale C) | B33: =B31-B32 -> -50200
A35: RISULTATO PRIMA DELLE IMPOSTE (A-B+/-C) | B35: =B28+B33 -> 555700
A36: 20) Imposte sul reddito (correnti, differite, anticipate) | B36: =SUMIFS('Piano dei Conti'!G2:G455,'Piano dei Conti'!A2:A455,"480.005.*",'Piano dei Conti'!B2:B455,"Sottoconto")-SUMIFS('Piano dei Conti'!H2:H455,'Piano dei Conti'!A2:A455,"480.005.*",'Piano dei Conti'!B2:B455,"Sottoconto") -> 167000
A38: 21) UTILE (PERDITA) DELL'ESERCIZIO | B38: =B35-B36 -> 388700

Sheet Schema SP CEE
A1: Voce di bilancio | B1: Riferimento PdC
A2: ATTIVO
A3: A) Crediti verso soci per versamenti ancora dovuti
A4: B) IMMOBILIZZAZIONI
A5: I - Immobilizzazioni immateriali | B5: Mastro 010
A6: II - Immobilizzazioni materiali | B6: Mastro 020
A7: III - Immobilizzazioni finanziarie | B7: Mastro 030
A8: C) ATTIVO CIRCOLANTE
A9: I - Rimanenze | B9: Mastro 040
A10: II - Crediti | B10: Mastro 050
A11: III - Attivita' finanziarie non immobilizzate | B11: Mastro 060
A12: IV - Disponibilita' liquide | B12: Mastro 070
A13: D) RATEI E RISCONTI ATTIVI | B13: Mastro 080
A15: PASSIVO
A16: A) PATRIMONIO NETTO | B16: Mastro 100
A17: B) FONDI PER RISCHI E ONERI | B17: Mastro 110
A18: C) TRATTAMENTO DI FINE RAPPORTO | B18: Mastro 120
A19: D) DEBITI | B19: Mastro 130
A20: E) RATEI E RISCONTI PASSIVI | B20: Mastro 180

Sheet Legenda
A1: Termine / sigla | B1: Spiegazione
A2: LIVELLO
A3: Mastro | B3: Livello 1 - aggregazione di alto livello (es. 'Immob. Materiali'). Sintetico, non si movimenta direttamente.
A4: Conto | B4: Livello 2 - sottoinsieme tematico di un mastro. Sintetico, non si movimenta direttamente.
A5: Sottoconto | B5: Livello 3 - foglia operativa, e' qui che si registrano le scritture in prima nota.
A7: NATURA
A8: Attivo Patrim. | B8: Voce dello Stato Patrimoniale - sezione Attivo (saldo Dare).
A9: Passivo Patrim. | B9: Voce dello Stato Patrimoniale - sezione Passivo (saldo Avere).
A10: Patrimonio Netto | B10: Capitale e riserve della societa' (saldo Avere; perdite hanno saldo Dare).
A11: Costo (CE) | B11: Voce del Conto Economico - costo (saldo Dare).
A12: Ricavo (CE) | B12: Voce del Conto Economico - ricavo o provento (saldo Avere).
A13: Rettifica (fondo) | B13: Conto rettificativo dell'attivo (es. fondo amm.to). Saldo Avere ma classificato in detrazione dell'attivo.
A15: D/A
A16: D | B16: Saldo normale in DARE (attivita', costi).
A17: A | B17: Saldo normale in AVERE (passivita', PN, ricavi, fondi).
A19: RIFERIMENTI NORMATIVI / OIC
A20: Codice Civile | B20: Artt. 2424 (SP), 2425 (CE), 2426 (criteri valutazione), 2427 (nota integrativa).
A21: D.Lgs. 139/2015 | B21: Riforma del bilancio: eliminazione conti d'ordine, introduzione strumenti derivati.
A22: OIC 9 | B22: Svalutazioni delle immobilizzazioni materiali e immateriali.
A23: OIC 13 | B23: Rimanenze.
A24: OIC 15 | B24: Crediti.
A25: OIC 16 | B25: Immobilizzazioni materiali.
A26: OIC 18 | B26: Ratei e risconti.
A27: OIC 19 | B27: Debiti.
A28: OIC 23 | B28: Lavori in corso su ordinazione.
A29: OIC 24 | B29: Immobilizzazioni immateriali.
A30: OIC 25 | B30: Imposte sul reddito (correnti, differite, anticipate).
A31: OIC 28 | B31: Patrimonio netto.
... A33: OIC 32 | B33: Strumenti finanziari derivati.
